Workbook

Sheet Sheet3
B1: Date | C1: TAMO | D1: Maruti | E1: Mahindra | F1: Bajaj | G1: Eicher
B2: 45207 | C2: 665.05 | D2: 10727.55 | E2: 1562.45 | F2: 5052.4 | G2: 3476.4
B3: 45214 | C3: 661.16 | D3: 10725.65 | E3: 1558.25 | F3: 5489.3 | G3: 3480.9
B4: 45221 | C4: 639.08 | D4: 10560.7 | E4: 1510.8 | F4: 5373.55 | G4: 3394.85
B5: 45228 | C5: 645.51 | D5: 10276.3 | E5: 1469 | F5: 5368.95 | G5: 3428
B6: 45235 | C6: 649.05 | D6: 10388.8 | E6: 1524.1 | F6: 5392.05 | G6: 3540.75
B7: 45242 | C7: 679.45 | D7: 10523.5 | E7: 1584.55 | F7: 5631.5 | G7: 3865.3
B8: 45249 | C8: 671.63 | D8: 10515.65 | E8: 1553.2 | F8: 5930.3 | G8: 3849.05
B9: 45256 | C9: 703.28 | D9: 10585.7 | E9: 1625.5 | F9: 6046.05 | G9: 3891.2
B10: 45263 | C10: 712.35 | D10: 10618.55 | E10: 1668.55 | F10: 6075.7 | G10: 4055
B11: 45270 | C11: 730.15 | D11: 10286.4 | E11: 1724.95 | F11: 6275.2 | G11: 4059.9
B12: 45277 | C12: 722.47 | D12: 10217.15 | E12: 1634.25 | F12: 6372.1 | G12: 4006.05
B13: 45284 | C13: 777.55 | D13: 10302.35 | E13: 1729.4 | F13: 6797.25 | G13: 4143.5
... B105: 45928 | C105: 716.1 | D105: 15806 | E105: 3462 | F105: 8679.5 | G105: 6941

Sheet Data Input
B2: Date | C2: Price | E2: Shareholder's name | F2: No. Share (Crs) | G2: Shareholding (%) | H2: Market value (Crs)
B3: 45936 | C3: 712.65 | E3: Tata Sons Private Limited | F3: 147.82635 | G3: 40.15 | H3: =F3*716 -> 105843.67
B4: 45933 | C4: 716.1 | E4: Life Insurance Corporation Of India | F4: 14.332928 | G4: 3.89 | H4: =F4*716 -> 10262.377
B5: 45931 | C5: 718.35 | E5: SBI Nifty 50 Etf | F5: 10.253439 | G5: 2.79 | H5: =F5*716 -> 7341.4621
B6: 45930 | C6: 680.2 | E6: Tata Industries Limited | F6: 7.220363 | G6: 1.96 | H6: =F6*716 -> 5169.7799
B7: 45929 | C7: 672.5 | E7: ICICI Prudential Value Discovery Fund | F7: 6.8270492 | G7: 1.85 | H7: =F7*716 -> 4888.1672
B8: 45926 | C8: 672.9 | E8: HDFC Trustee Company Ltd. A/C Hdfc Large Cap Fund | F8: 4.9420875 | G8: 1.34 | H8: =F8*716 -> 3538.5347
B9: 45925 | C9: 664.3 | E9: Rekha Jhunjhunwala | F9: 4.777026 | G9: 1.3 | H9: =F9*716 -> 3420.3506
B10: 45924 | C10: 682.95 | E10: Tata Investment Corporation Limited | F10: 1.1 | G10: 0.3 | H10: =F10*716 -> 787.6
B11: 45923 | C11: 701.35 | E11: Investor Education and Protection Fund (IEPF) | F11: 0.9768824 | G11: 0.27 | H11: =F11*716 -> 699.4478
B12: 45922 | C12: 696.25 | E12: Ewart Investments Limited | F12: 0.3383746 | G12: 0.09 | H12: =F12*716 -> 242.27621
B13: 45919 | C13: 707.45
B14: 45918 | C14: 711.2 | E14: Promoters | F14: 0.4257
B15: 45917 | C15: 719.15 | E15: FII | F15: 0.1717
B16: 45916 | C16: 713.25 | E16: DII | F16: 0.1693
B17: 45915 | C17: 712.9 | E17: Public & Government | F17: =23.01%+0.31% -> 0.2332
B18: 45912 | C18: 715.25
B19: 45911 | C19: 705.85
B20: 45910 | C20: 709.1
B21: 45909 | C21: 715.55
B22: 45908 | C22: 719.5
B23: 45905 | C23: 691.7
B24: 45904 | C24: 687.5
B25: 45903 | C25: 692.05
B26: 45902 | C26: 684.4
B27: 45901 | C27: 690.15
B28: 45898 | C28: 669
B29: 45897 | C29: 675.45
... B1242: 44111 | C1242: 141

Sheet Teaser
B2: ='Data Sheet'!B1&" - One Page Profile" -> TATA MOTORS LTD - One Page Profile
C4: Tata Motors Group is a leading global automobile manufacturer. Part of the illustrious multi-national conglomerate, the Tata group, it offers a wide and diverse portfolio of cars, sports utility vehicles, trucks, buses and defence vehicles to the world.It has operations in India, the UK, South Korea, South Africa, China, Brazil, Austria and Slovakia through a strong global network of subsidiaries, associate companies and Joint Ventures (JVs), including Jaguar Land Rover in the UK and Tata Daewoo in South Korea.
B6: INR(in Crs)
B7: Key Financial metrics | C7: ='Data Sheet'!G16 -> 44286 | D7: ='Data Sheet'!H16 -> 44651 | E7: ='Data Sheet'!I16 -> 45016 | F7: ='Data Sheet'!J16 -> 45382 | G7: ='Data Sheet'!K16 -> 45747 | I7: Share Price - 5Y
B9: Total Sales | C9: ='Data Sheet'!G17 -> 249794.75 | D9: ='Data Sheet'!H17 -> 278453.62 | E9: ='Data Sheet'!I17 -> 345966.97 | F9: ='Data Sheet'!J17 -> 434016 | G9: ='Data Sheet'!K17 -> 439695
B10: Sales Growth (YOY %) | C10: ='Data Sheet'!G36 -> -0.043181168 | D10: ='Data Sheet'!H36 -> 0.11472967 | E10: ='Data Sheet'!I36 -> 0.24245815 | F10: ='Data Sheet'!J36 -> 0.25450126 | G10: ='Data Sheet'!K36 -> 0.013084771
B11: Gross profit Margin (%) | C11: ='Data Sheet'!G38 -> 0.36624273 | D11: ='Data Sheet'!H38 -> 0.32013629 | E11: ='Data Sheet'!I38 -> 0.27648532 | F11: ='Data Sheet'!J38 -> 0.31909884 | G11: ='Data Sheet'!K38 -> 0.34643332
B12: EBITDA Margins (%) | C12: ='Data Sheet'!G35 -> 0.083005548 | D12: ='Data Sheet'!H35 -> 0.096739163 | E12: ='Data Sheet'!I35 -> 0.11042728 | F12: ='Data Sheet'!J35 -> 0.14333112 | G12: ='Data Sheet'!K35 -> 0.15163011
B13: EBIT Margins (%) | C13: ='Data Sheet'!G39 -> -0.011258683 | D13: ='Data Sheet'!H39 -> 0.0075476842 | E13: ='Data Sheet'!I39 -> 0.038569665 | F13: ='Data Sheet'!J39 -> 0.080570762 | G13: ='Data Sheet'!K39 -> 0.098738899
B14: Net Profit Margins (%) | C14: ='Data Sheet'!G40 -> -0.053849771 | D14: ='Data Sheet'!H40 -> -0.04108932 | E14: ='Data Sheet'!I40 -> 0.0069783829 | F14: ='Data Sheet'!J40 -> 0.072345259 | G14: ='Data Sheet'!K40 -> 0.063293874
B15: Earnings Per Share (In Rs.) | C15: ='Historical FS'!H44 -> -6.1453869 | D15: ='Historical FS'!I44 -> -41.137096 | E15: ='Historical FS'!J44 -> -11.967657 | F15: ='Historical FS'!K44 -> 81.338632 | G15: ='Historical FS'!L44 -> 49.267383
B16: EPS Growth (YOY %) | C16: ='Historical FS'!H45 -> -0.83981519 | D16: ='Historical FS'!I45 -> 5.6939799 | E16: ='Historical FS'!J45 -> -0.7090787 | F16: ='Historical FS'!K45 -> -7.7965375 | G16: ='Historical FS'!L45 -> -0.39429295
B17: Dividend Per Share | C17: ='Historical FS'!H47 -> 0 | D17: ='Historical FS'!I47 -> 0 | E17: ='Historical FS'!J47 -> 2.3068028 | F17: ='Historical FS'!K47 -> 6.9280101 | G17: ='Historical FS'!L47 -> 6.6431988
B18: DPS Growth (YOY %) | C18: N/A | D18: N/A | E18: N/A | F18: =F17/E17-1 -> 2.0032954 | G18: =G17/F17-1 -> -0.041110112
B20: Key Financial Ratios | C20: =C7 -> 44286 | D20: =D7 -> 44651 | E20: =E7 -> 45016 | F20: =F7 -> 45382 | G20: =G7 -> 45747 | I20: Share Price - 5Y
B22: Price to Earnings | C22: ='[1]Profit & Loss'!G14 -> 0 | D22: ='[1]Profit & Loss'!H14 -> 0 | E22: ='[1]Profit & Loss'!I14 -> 0 | F22: ='[1]Profit & Loss'!J14 -> 0 | G22: ='[1]Profit & Loss'!K14 -> 0
B23: EV/EBITDA | C23: ='Data Sheet'!G103 -> 5.6565774 | D23: ='Data Sheet'!H103 -> 7.6468673 | E23: ='Data Sheet'!I103 -> 6.3116962 | F23: ='Data Sheet'!J103 -> 3.2345889 | G23: ='Data Sheet'!K103 -> 5.4098924
B24: EV/Sales | C24: ='Data Sheet'!G104 -> 0.4695273 | D24: ='Data Sheet'!H104 -> 0.73975154 | E24: ='Data Sheet'!I104 -> 0.69698342 | F24: ='Data Sheet'!J104 -> 0.46361725 | G24: ='Data Sheet'!K104 -> 0.82030256
B25: Price to Book Value | C25: ='Data Sheet'!G107 -> 0.3972606 | D25: ='Data Sheet'!H107 -> 2.2487403 | E25: ='Data Sheet'!I107 -> 3.1780599 | F25: ='Data Sheet'!J107 -> 1.6458266 | G25: ='Data Sheet'!K107 -> 2.8411019
B26: Return on Equity (%) | C26: -0.24347853 | D26: -0.25675834 | E26: 0.053269961 | F26: 0.36975671 | G26: 0.23961634
B27: Return on Capital Employed (%) | C27: -0.012340819 | D27: 0.011887353 | E27: 0.073529898 | F27: 0.19039483 | G27: 0.23026014
B29: Top 10 Share Holders | C29: ='Data Input'!F2 -> No. Share (Crs) | E29: Holdings (%) | F29: ='Data Input'!H2 -> Market value (Crs) | I29: Shareholding Pattern
B31: ='Data Input'!E3 -> Tata Sons Private Limited | C31: ='Data Input'!F3 -> 147.82635 | E31: =('Data Input'!G3)/100 -> 0.4015 | F31: ='Data Input'!H3 -> 105843.67
B32: ='Data Input'!E4 -> Life Insurance Corporation Of India | C32: ='Data Input'!F4 -> 14.332928 | E32: =('Data Input'!G4)/100 -> 0.0389 | F32: ='Data Input'!H4 -> 10262.377
B33: ='Data Input'!E5 -> SBI Nifty 50 Etf | C33: ='Data Input'!F5 -> 10.253439 | E33: =('Data Input'!G5)/100 -> 0.0279 | F33: ='Data Input'!H5 -> 7341.4621
B34: ='Data Input'!E6 -> Tata Industries Limited | C34: ='Data Input'!F6 -> 7.220363 | E34: =('Data Input'!G6)/100 -> 0.0196 | F34: ='Data Input'!H6 -> 5169.7799
B35: ='Data Input'!E7 -> ICICI Prudential Value Discovery Fund | C35: ='Data Input'!F7 -> 6.8270492 | E35: =('Data Input'!G7)/100 -> 0.0185 | F35: ='Data Input'!H7 -> 4888.1672
B36: ='Data Input'!E8 -> HDFC Trustee Company Ltd. A/C Hdfc Large Cap Fund | C36: ='Data Input'!F8 -> 4.9420875 | E36: =('Data Input'!G8)/100 -> 0.0134 | F36: ='Data Input'!H8 -> 3538.5347
B37: ='Data Input'!E9 -> Rekha Jhunjhunwala | C37: ='Data Input'!F9 -> 4.777026 | E37: =('Data Input'!G9)/100 -> 0.013 | F37: ='Data Input'!H9 -> 3420.3506
B38: ='Data Input'!E10 -> Tata Investment Corporation Limited | C38: ='Data Input'!F10 -> 1.1 | E38: =('Data Input'!G10)/100 -> 0.003 | F38: ='Data Input'!H10 -> 787.6
B39: ='Data Input'!E11 -> Investor Education and Protection Fund (IEPF) | C39: ='Data Input'!F11 -> 0.9768824 | E39: =('Data Input'!G11)/100 -> 0.0027 | F39: ='Data Input'!H11 -> 699.4478
B40: ='Data Input'!E12 -> Ewart Investments Limited | C40: ='Data Input'!F12 -> 0.3383746 | E40: =('Data Input'!G12)/100 -> 0.0009 | F40: ='Data Input'!H12 -> 242.27621
B42: Managerial Remuneration | D42: Designation | E42: Remuneration | F42: X of Median Salary | I42: Capital Structure
B44: Mr N Chandrasekaran | C44: Chairman & Non Exec. Director | E44: =F44 -> N/A | F44: =C18 -> N/A | I44: Share Price as on 05.10.2025 | K44: ='Data Sheet'!B8 -> 716.1
B45: Mr Girish Wagh | C45: Exec. Director | E45: 165.57 | F45: 69.31:1 | I45: Number of Shares O/s | K45: ='Data Sheet'!B6 -> 368.22747
B46: Mr Om Prakash Bhatt | C46: Independent Director | E46: 115 | F46: 10.44:1 | I46: Market Capitalization | K46: =K44*K45 -> 263687.69
B47: Ms Hanne Sorenson | C47: Independent Director | E47: 115 | F47: 10.32:1 | I47: Less: Cash & Equivalents | K47: =-'Data Sheet'!K71 -> -40834
B48: Ms Vedika Bhandarkar | C48: Independent Director | E48: 115 | F48: 10.21:1 | I48: Add: Total Debt | K48: ='Data Sheet'!K61 -> 71540
B49: Mr Kosaraju Veerayya Chowdary | C49: Independent Director | E49: 115 | F49: 10.18:1 | I49: Add: Minority Interest | K49: 6610
B50: Mr Al Noor Ramji | C50: Independent Director | E50: 115 | F50: 10.15:1 | I50: Enterprise Value | K50: =SUM(K46:K49) -> 301003.69
...

Sheet WACC-->

Sheet Historical FS
B2: TATA MOTORS LTD
B3: ( TATA MOTORS LTD | BSE Code : 500570 )
B4: INR 716.00 (as on 05.10.2025)
B5: 52 Week ( High - INR 948.45 & Low - 535.75)
B8: ="Historical Financial Statements - "&'[3]Data Sheet'!B1 -> Historical Financial Statements - TATA MOTORS LTD
B9: Years | C9: ='[3]Data Sheet'!B16 -> 42460 | D9: ='[3]Data Sheet'!C16 -> 42825 | E9: ='[3]Data Sheet'!D16 -> 43190 | F9: ='[3]Data Sheet'!E16 -> 43555 | G9: ='[3]Data Sheet'!F16 -> 43921 | H9: ='[3]Data Sheet'!G16 -> 44286 | I9: ='[3]Data Sheet'!H16 -> 44651 | J9: ='[3]Data Sheet'!I16 -> 45016 | ... L9: ='[3]Data Sheet'!K16 -> 45747 | M9: LTM
A11: x | B11: Income Statement
B12: Sales | C12: =IFERROR('[3]Data Sheet'!B17,0) -> 273045.6 | D12: =IFERROR('[3]Data Sheet'!C17,0) -> 269692.51 | E12: =IFERROR('[3]Data Sheet'!D17,0) -> 291550.48 | F12: =IFERROR('[3]Data Sheet'!E17,0) -> 301938.4 | G12: =IFERROR('[3]Data Sheet'!F17,0) -> 261067.97 | H12: =IFERROR('[3]Data Sheet'!G17,0) -> 249794.75 | I12: =IFERROR('[3]Data Sheet'!H17,0) -> 278453.62 | J12: =IFERROR('[3]Data Sheet'!I17,0) -> 345966.97 | ... L12: =IFERROR('[3]Data Sheet'!K17,0) -> 439695 | M12: =IFERROR(SUM('[3]Data Sheet'!H42:K42),0) -> 437968
B13: Sales Growth | C13: - | D13: =D12/C12-1 -> -0.01228033 | E13: =E12/D12-1 -> 0.081047746 | F13: =F12/E12-1 -> 0.035629919 | G13: =G12/F12-1 -> -0.13536016 | H13: =H12/G12-1 -> -0.043181168 | I13: =I12/H12-1 -> 0.11472967 | J13: =J12/I12-1 -> 0.24245815 | K13: =K12/J12-1 -> 0.25450126 | ... M13: =M12/L12-1 -> -0.0039277226
B15: COGS | C15: =IFERROR(SUM('[3]Data Sheet'!B18,'[3]Data Sheet'!B20,'[3]Data Sheet'!B21,'[3]Data Sheet'!B22)-1*'[3]Data Sheet'!B19,0) -> 205509.07 | D15: =IFERROR(SUM('[3]Data Sheet'!C18,'[3]Data Sheet'!C20,'[3]Data Sheet'!C21,'[3]Data Sheet'!C22)-1*'[3]Data Sheet'!C19,0) -> 205454.24 | E15: =IFERROR(SUM('[3]Data Sheet'!D18,'[3]Data Sheet'!D20,'[3]Data Sheet'!D21,'[3]Data Sheet'!D22)-1*'[3]Data Sheet'!D19,0) -> 228429.83 | F15: =IFERROR(SUM('[3]Data Sheet'!E18,'[3]Data Sheet'!E20,'[3]Data Sheet'!E21,'[3]Data Sheet'!E22)-1*'[3]Data Sheet'!E19,0) -> 242845.53 | G15: =IFERROR(SUM('[3]Data Sheet'!F18,'[3]Data Sheet'!F20,'[3]Data Sheet'!F21,'[3]Data Sheet'!F22)-1*'[3]Data Sheet'!F19,0) -> 210376.07 | H15: =IFERROR(SUM('[3]Data Sheet'!G18,'[3]Data Sheet'!G20,'[3]Data Sheet'!G21,'[3]Data Sheet'!G22)-1*'[3]Data Sheet'!G19,0) -> 195326.04 | I15: =IFERROR(SUM('[3]Data Sheet'!H18,'[3]Data Sheet'!H20,'[3]Data Sheet'!H21,'[3]Data Sheet'!H22)-1*'[3]Data Sheet'!H19,0) -> 223300.01 | J15: =IFERROR(SUM('[3]Data Sheet'!I18,'[3]Data Sheet'!I20,'[3]Data Sheet'!I21,'[3]Data Sheet'!I22)-1*'[3]Data Sheet'!I19,0) -> 274403.64 | ... L15: =IFERROR(SUM('[3]Data Sheet'!K18,'[3]Data Sheet'!K20,'[3]Data Sheet'!K21,'[3]Data Sheet'!K22)-1*'[3]Data Sheet'!K19,0) -> 340809 | M15: =IFERROR(SUM('[3]Data Sheet'!H43:K43),0) -> 386344
B16: COGS %Sales | C16: =C15/C12 -> 0.75265476 | D16: =D15/D12 -> 0.76180922 | E16: =E15/E12 -> 0.7835001 | F16: =F15/F12 -> 0.80428833 | G16: =G15/G12 -> 0.80582873 | H16: =H15/H12 -> 0.78194614 | I16: =I15/I12 -> 0.80192892 | J16: =J15/J12 -> 0.79314982 | ... M16: =M15/M12 -> 0.88212837
B18: Gross Proft | C18: =C12-C15 -> 67536.53 | D18: =D12-D15 -> 64238.27 | E18: =E12-E15 -> 63120.65 | F18: =F12-F15 -> 59092.87 | G18: =G12-G15 -> 50691.9 | H18: =H12-H15 -> 54468.71 | I18: =I12-I15 -> 55153.61 | J18: =J12-J15 -> 71563.33 | ... M18: =M12-M15 -> 51624
B19: Gross Margins | C19: =C18/C12 -> 0.24734524 | D19: =D18/D12 -> 0.23819078 | E19: =E18/E12 -> 0.2164999 | F19: =F18/F12 -> 0.19571167 | G19: =G18/G12 -> 0.19417127 | H19: =H18/H12 -> 0.21805386 | I19: =I18/I12 -> 0.19807108 | J19: =J18/J12 -> 0.20685018 | ... M19: =M18/M12 -> 0.11787163
B21: Selling & Genral Expenses | C21: =IFERROR(SUM('[3]Data Sheet'!B23:B24),0) -> 29141.28 | D21: =IFERROR(SUM('[3]Data Sheet'!C23:C24),0) -> 34649.58 | E21: =IFERROR(SUM('[3]Data Sheet'!D23:D24),0) -> 31662.97 | F21: =IFERROR(SUM('[3]Data Sheet'!E23:E24),0) -> 34428.54 | G21: =IFERROR(SUM('[3]Data Sheet'!F23:F24),0) -> 32704.83 | H21: =IFERROR(SUM('[3]Data Sheet'!G23:G24),0) -> 22181.28 | I21: =IFERROR(SUM('[3]Data Sheet'!H23:H24),0) -> 30433.52 | J21: =IFERROR(SUM('[3]Data Sheet'!I23:I24),0) -> 39747.53 | ... L21: =IFERROR(SUM('[3]Data Sheet'!K23:K24),0) -> 43670 | M21: 0
B22: S&G Expenses %Sales | C22: =C21/C12 -> 0.10672679 | D22: =D21/D12 -> 0.1284781 | E22: =E21/E12 -> 0.10860202 | F22: =F21/F12 -> 0.11402505 | G22: =G21/G12 -> 0.12527324 | H22: =H21/H12 -> 0.088798023 | I22: =I21/I12 -> 0.10929475 | J22: =J21/J12 -> 0.11488822 | ... M22: =M21/M12 -> 0
B24: EBITDA | C24: =C18-C21 -> 38395.25 | D24: =D18-D21 -> 29588.69 | E24: =E18-E21 -> 31457.68 | F24: =F18-F21 -> 24664.33 | G24: =G18-G21 -> 17987.07 | H24: =H18-H21 -> 32287.43 | I24: =I18-I21 -> 24720.09 | J24: =J18-J21 -> 31815.8 | ... L24: =L18-L21 -> 55216 | M24: =IFERROR(SUM('[3]Data Sheet'!H51:K51),0) -> 57272
B25: EBITDA %Sales | C25: =C24/C12 -> 0.14061845 | D25: =D24/D12 -> 0.10971269 | E25: =E24/E12 -> 0.10789788 | F25: =F24/F12 -> 0.081686629 | G25: =G24/G12 -> 0.068898034 | H25: =H24/H12 -> 0.12925584 | I25: =I24/I12 -> 0.088776328 | J25: =J24/J12 -> 0.091961958 | ... M25: =M24/M12 -> 0.13076754
B27: Interest | C27: =IFERROR('[3]Data Sheet'!B27,0) -> 4889.08 | D27: =IFERROR('[3]Data Sheet'!C27,0) -> 4238.01 | E27: =IFERROR('[3]Data Sheet'!D27,0) -> 4681.79 | F27: =IFERROR('[3]Data Sheet'!E27,0) -> 5758.6 | G27: =IFERROR('[3]Data Sheet'!F27,0) -> 7243.33 | H27: =IFERROR('[3]Data Sheet'!G27,0) -> 8097.17 | I27: =IFERROR('[3]Data Sheet'!H27,0) -> 9311.86 | J27: =IFERROR('[3]Data Sheet'!I27,0) -> 10225.48 | ... L27: =IFERROR('[3]Data Sheet'!K27,0) -> 5083 | M27: =IFERROR(SUM('[3]Data Sheet'!H27:K27),0) -> 32214.34
B28: Interest %Sales | C28: =C27/C12 -> 0.017905727 | D28: =D27/D12 -> 0.01571423 | E28: =E27/E12 -> 0.016058248 | F28: =F27/F12 -> 0.019072102 | G28: =G27/G12 -> 0.027744997 | H28: =H27/H12 -> 0.032415293 | I28: =I27/I12 -> 0.033441332 | J28: =J27/J12 -> 0.029556232 | ... M28: =M27/M12 -> 0.073554095
B30: Depriciation | C30: =IFERROR('[3]Data Sheet'!B26,0) -> 16710.78 | D30: =IFERROR('[3]Data Sheet'!C26,0) -> 17904.99 | E30: =IFERROR('[3]Data Sheet'!D26,0) -> 21553.59 | F30: =IFERROR('[3]Data Sheet'!E26,0) -> 23590.63 | G30: =IFERROR('[3]Data Sheet'!F26,0) -> 21425.43 | H30: =IFERROR('[3]Data Sheet'!G26,0) -> 23546.71 | I30: =IFERROR('[3]Data Sheet'!H26,0) -> 24835.69 | J30: =IFERROR('[3]Data Sheet'!I26,0) -> 24860.36 | ... L30: =IFERROR('[3]Data Sheet'!K26,0) -> 23256 | M30: =IFERROR(SUM('[3]Data Sheet'!H45:K45),0) -> 22019
B31: Depriciation %Sales | C31: =C30/C12 -> 0.061201426 | D31: =D30/D12 -> 0.066390387 | E31: =E30/E12 -> 0.073927472 | F31: =F30/F12 -> 0.078130605 | G31: =G30/G12 -> 0.082068398 | H31: =H30/H12 -> 0.094264231 | I31: =I30/I12 -> 0.089191478 | J31: =J30/J12 -> 0.071857611 | ... M31: =M30/M12 -> 0.050275363
B33: Earnings Before Tax | C33: =IFERROR(C24-SUM(C27,C30),0) -> 16795.39 | D33: =IFERROR(D24-SUM(D27,D30),0) -> 7445.69 | E33: =IFERROR(E24-SUM(E27,E30),0) -> 5222.3 | F33: =IFERROR(F24-SUM(F27,F30),0) -> -4684.9 | G33: =IFERROR(G24-SUM(G27,G30),0) -> -10681.69 | H33: =IFERROR(H24-SUM(H27,H30),0) -> 643.55 | I33: =IFERROR(I24-SUM(I27,I30),0) -> -9427.46 | J33: =IFERROR(J24-SUM(J27,J30),0) -> -3270.04 | ... L33: =IFERROR(L24-SUM(L27,L30),0) -> 26877 | M33: =IFERROR(SUM('[3]Data Sheet'!H47:K47),0) -> 30437
B34: EBT %Sales | C34: =C33/C12 -> 0.061511301 | D34: =D33/D12 -> 0.027608071 | E34: =E33/E12 -> 0.017912164 | F34: =F33/F12 -> -0.015516079 | G34: =G33/G12 -> -0.04091536 | H34: =H33/H12 -> 0.0025763152 | I34: =I33/I12 -> -0.033856482 | J34: =J33/J12 -> -0.009451885 | ... M34: =M33/M12 -> 0.069495945
B36: Tax | C36: =IFERROR('[3]Data Sheet'!B29,0) -> 3025.05 | D36: =IFERROR('[3]Data Sheet'!C29,0) -> 3251.23 | E36: =IFERROR('[3]Data Sheet'!D29,0) -> 4341.93 | F36: =IFERROR('[3]Data Sheet'!E29,0) -> -2437.45 | G36: =IFERROR('[3]Data Sheet'!F29,0) -> 395.25 | H36: =IFERROR('[3]Data Sheet'!G29,0) -> 2541.86 | I36: =IFERROR('[3]Data Sheet'!H29,0) -> 4231.29 | J36: =IFERROR('[3]Data Sheet'!I29,0) -> 704.06 | ... L36: =IFERROR('[3]Data Sheet'!K29,0) -> 10502 | M36: =IFERROR(SUM('[3]Data Sheet'!H48:K48),0) -> 8943
B37: Effective Tax Rate | C37: =C36/C33 -> 0.18011192 | D37: =D36/D33 -> 0.43665933 | E37: =E36/E33 -> 0.83142102 | F37: =F36/F33 -> 0.52027791 | G37: =G36/G33 -> -0.037002572 | H37: =H36/H33 -> 3.9497475 | I37: =I36/I33 -> -0.44882609 | J37: =J36/J33 -> -0.21530623 | ... M37: =M36/M33 -> 0.29382002
B39: Net Profit | C39: =IFERROR(C33-C36,0) -> 13770.34 | D39: =IFERROR(D33-D36,0) -> 4194.46 | E39: =IFERROR(E33-E36,0) -> 880.37 | F39: =IFERROR(F33-F36,0) -> -2247.45 | G39: =IFERROR(G33-G36,0) -> -11076.94 | H39: =IFERROR(H33-H36,0) -> -1898.31 | I39: =IFERROR(I33-I36,0) -> -13658.75 | J39: =IFERROR(J33-J36,0) -> -3974.1 | ... M39: =IFERROR(M33-M36,0) -> 21494
B40: Net Margins | C40: =C39/C12 -> 0.050432382 | D40: =D39/D12 -> 0.015552749 | E40: =E39/E12 -> 0.0030196143 | F40: =F39/F12 -> -0.0074434057 | G40: =G39/G12 -> -0.042429334 | H40: =H39/H12 -> -0.0075994792 | I40: =I39/I12 -> -0.049052155 | J40: =J39/J12 -> -0.011486935 | ... M40: =M39/M12 -> 0.049076645
B42: No. of Equity Shares | C42: =IFERROR('[3]Data Sheet'!B94,0) -> 288.74 | D42: =IFERROR('[3]Data Sheet'!C94,0) -> 288.72 | E42: =IFERROR('[3]Data Sheet'!D94,0) -> 288.73 | F42: =IFERROR('[3]Data Sheet'!E94,0) -> 288.73 | G42: =IFERROR('[3]Data Sheet'!F94,0) -> 288.73 | H42: =IFERROR('[3]Data Sheet'!G94,0) -> 308.9 | I42: =IFERROR('[3]Data Sheet'!H94,0) -> 332.03 | J42: =IFERROR('[3]Data Sheet'!I94,0) -> 332.07 | ... L42: =IFERROR('[3]Data Sheet'!K94,0) -> 332.37 | M42: =L42 -> 332.37
B44: Earning per Share | C44: =IFERROR(C39/C42,0) -> 47.691141 | D44: =IFERROR(D39/D42,0) -> 14.527778 | E44: =IFERROR(E39/E42,0) -> 3.0491116 | F44: =IFERROR(F39/F42,0) -> -7.7839158 | G44: =IFERROR(G39/G42,0) -> -38.364354 | H44: =IFERROR(H39/H42,0) -> -6.1453869 | I44: =IFERROR(I39/I42,0) -> -41.137096 | J44: =IFERROR(J39/J42,0) -> -11.967657 | ... M44: =IFERROR(M39/M42,0) -> 64.668893
B45: EPS Growth % | D45: =IFERROR(D44/C44-1,0) -> -0.69537785 | E45: =E44/D44-1 -> -0.79011851 | F45: =F44/E44-1 -> -3.5528471 | G45: =G44/F44-1 -> 3.9286703 | H45: =H44/G44-1 -> -0.83981519 | I45: =I44/H44-1 -> 5.6939799 | J45: =J44/I44-1 -> -0.7090787 | K45: =K44/J44-1 -> -7.7965375 | L45: =L44/K44-1 -> -0.39429295 | M45: =M44/L44-1 -> 0.31261069
B47: Dividend per Share | C47: =IFERROR('[3]Data Sheet'!B31/C42,0) -> 0.23522893 | D47: =IFERROR('[3]Data Sheet'!C31/D42,0) -> 0 | E47: =IFERROR('[3]Data Sheet'!D31/E42,0) -> 0 | F47: =IFERROR('[3]Data Sheet'!E31/F42,0) -> 0 | G47: =IFERROR('[3]Data Sheet'!F31/G42,0) -> 0 | H47: =IFERROR('[3]Data Sheet'!G31/H42,0) -> 0 | I47: =IFERROR('[3]Data Sheet'!H31/I42,0) -> 0 | J47: =IFERROR('[3]Data Sheet'!I31/J42,0) -> 2.3068028 | ... M47: =IFERROR('[3]Data Sheet'!L31/M42,0) -> 0
B48: Dividend Payout ratio | C48: =IFERROR(C47/C44,0) -> 0.0049323401 | D48: =IFERROR(D47/D44,0) -> 0 | E48: =IFERROR(E47/E44,0) -> 0 | F48: =IFERROR(F47/F44,0) -> 0 | G48: =IFERROR(G47/G44,0) -> 0 | H48: =IFERROR(H47/H44,0) -> 0 | I48: =IFERROR(I47/I44,0) -> 0 | J48: =IFERROR(J47/J44,0) -> -0.19275308 | ... M48: =IFERROR(M47/M44,0) -> 0
B50: Retained Earnings | C50: =IFERROR(IF(C44>C47,1-C48,0),0) -> 0.99506766 | D50: =IFERROR(IF(D44>D47,1-D48,0),0) -> 1 | E50: =IFERROR(IF(E44>E47,1-E48,0),0) -> 1 | F50: =IFERROR(IF(F44>F47,1-F48,0),0) -> 0 | G50: =IFERROR(IF(G44>G47,1-G48,0),0) -> 0 | H50: =IFERROR(IF(H44>H47,1-H48,0),0) -> 0 | I50: =IFERROR(IF(I44>I47,1-I48,0),0) -> 0 | J50: =IFERROR(IF(J44>J47,1-J48,0),0) -> 0 | ... M50: =IFERROR(IF(M44>M47,1-M48,0),0) -> 1
B52: TATA MOTORS LTD
B53: ( TATA MOTORS LTD | BSE Code : 500570 )
B54: INR 716.00 (as on 05.10.2025)
B55: 52 Week ( High - INR 948.45 & Low - 535.75)
B58: Balance Sheet
B59: Equity Share Capital | C59: =IFERROR('[3]Data Sheet'!B57,0) -> 679.18 | D59: =IFERROR('[3]Data Sheet'!C57,0) -> 679.22 | E59: =IFERROR('[3]Data Sheet'!D57,0) -> 679.22 | F59: =IFERROR('[3]Data Sheet'!E57,0) -> 679.22 | G59: =IFERROR('[3]Data Sheet'!F57,0) -> 719.54 | H59: =IFERROR('[3]Data Sheet'!G57,0) -> 765.81 | I59: =IFERROR('[3]Data Sheet'!H57,0) -> 765.88 | J59: =IFERROR('[3]Data Sheet'!I57,0) -> 766.02 | ... L59: =IFERROR('[3]Data Sheet'!K57,0) -> 736
B60: Reserves | C60: =IFERROR('[3]Data Sheet'!B58,0) -> 78273.23 | D60: =IFERROR('[3]Data Sheet'!C58,0) -> 57382.67 | E60: =IFERROR('[3]Data Sheet'!D58,0) -> 94748.69 | F60: =IFERROR('[3]Data Sheet'!E58,0) -> 59500.34 | G60: =IFERROR('[3]Data Sheet'!F58,0) -> 62358.99 | H60: =IFERROR('[3]Data Sheet'!G58,0) -> 54480.91 | I60: =IFERROR('[3]Data Sheet'!H58,0) -> 43795.36 | J60: =IFERROR('[3]Data Sheet'!I58,0) -> 44555.77 | ... L60: =IFERROR('[3]Data Sheet'!K58,0) -> 115408
...

Sheet Ratio Analysis
B2: TATA MOTORS LTD
B3: ( TATA MOTORS LTD | BSE Code : 500570 )
B4: INR 716.00 (as on 05.10.2025)
B5: 52 Week ( High - INR 948.45 & Low - 535.75)
B8: ="Ratio Analysis - "&'[3]Data Sheet'!B1 -> Ratio Analysis - TATA MOTORS LTD
B9: Years | C9: ='[3]Data Sheet'!B16 -> 42460 | D9: ='[3]Data Sheet'!C16 -> 42825 | E9: ='[3]Data Sheet'!D16 -> 43190 | F9: ='[3]Data Sheet'!E16 -> 43555 | G9: ='[3]Data Sheet'!F16 -> 43921 | H9: ='[3]Data Sheet'!G16 -> 44286 | I9: ='[3]Data Sheet'!H16 -> 44651 | J9: ='[3]Data Sheet'!I16 -> 45016 | ... L9: ='[3]Data Sheet'!K16 -> 45747 | M9: Trend | N9: Mean | O9: Median
B11: SalesGrowth | D11: =IFERROR([3]HistoricalFS!D7,0) -> -0.01228033 | E11: =IFERROR([3]HistoricalFS!E7,0) -> 0.081047746 | F11: =IFERROR([3]HistoricalFS!F7,0) -> 0.035629919 | G11: =IFERROR([3]HistoricalFS!G7,0) -> -0.13536016 | H11: =IFERROR([3]HistoricalFS!H7,0) -> -0.043181168 | I11: =IFERROR([3]HistoricalFS!I7,0) -> 0.11472967 | J11: =IFERROR([3]HistoricalFS!J7,0) -> 0.24245815 | K11: =IFERROR([3]HistoricalFS!K7,0) -> 0.25450126 | L11: =IFERROR([3]HistoricalFS!L7,0) -> 0.013084771 | N11: =IFERROR(AVERAGE(D11:L11),0) -> 0.061181096 | O11: =IFERROR(MEDIAN(C11:L11),0) -> 0.035629919
B12: EBITDA Growth | D12: =IFERROR([3]HistoricalFS!D18/[3]HistoricalFS!C18-1,0) -> -0.22936587 | E12: =IFERROR([3]HistoricalFS!E18/[3]HistoricalFS!D18-1,0) -> 0.063165689 | F12: =IFERROR([3]HistoricalFS!F18/[3]HistoricalFS!E18-1,0) -> -0.21595203 | G12: =IFERROR([3]HistoricalFS!G18/[3]HistoricalFS!F18-1,0) -> -0.27072538 | H12: =IFERROR([3]HistoricalFS!H18/[3]HistoricalFS!G18-1,0) -> 0.79503554 | I12: =IFERROR([3]HistoricalFS!I18/[3]HistoricalFS!H18-1,0) -> -0.23437418 | J12: =IFERROR([3]HistoricalFS!J18/[3]HistoricalFS!I18-1,0) -> 0.28704224 | K12: =IFERROR([3]HistoricalFS!K18/[3]HistoricalFS!J18-1,0) -> 0.81746176 | L12: =IFERROR([3]HistoricalFS!L18/[3]HistoricalFS!K18-1,0) -> -0.04510238 | N12: =IFERROR(AVERAGE(D12:L12),0) -> 0.10746504 | O12: =IFERROR(MEDIAN(C12:L12),0) -> -0.04510238
B13: EBIT Growth | D13: =IFERROR([3]HistoricalFS!D27/[3]HistoricalFS!C27-1,0) -> -0.55668252 | E13: =IFERROR([3]HistoricalFS!E27/[3]HistoricalFS!D27-1,0) -> -0.29861437 | F13: =IFERROR([3]HistoricalFS!F27/[3]HistoricalFS!E27-1,0) -> -1.8970951 | G13: =IFERROR([3]HistoricalFS!G27/[3]HistoricalFS!F27-1,0) -> 1.2800252 | H13: =IFERROR([3]HistoricalFS!H27/[3]HistoricalFS!G27-1,0) -> -1.060248 | I13: =IFERROR([3]HistoricalFS!I27/[3]HistoricalFS!H27-1,0) -> -15.649149 | J13: =IFERROR([3]HistoricalFS!J27/[3]HistoricalFS!I27-1,0) -> -0.65313669 | K13: =IFERROR([3]HistoricalFS!K27/[3]HistoricalFS!J27-1,0) -> -8.0308008 | L13: =IFERROR([3]HistoricalFS!L27/[3]HistoricalFS!K27-1,0) -> 0.16902266 | N13: =IFERROR(AVERAGE(D13:L13),0) -> -2.9662977 | O13: =IFERROR(MEDIAN(C13:L13),0) -> -0.65313669
B14: Net Profit Growth | D14: =IFERROR([3]HistoricalFS!D33/[3]HistoricalFS!C33-1,0) -> -0.69539895 | E14: =IFERROR([3]HistoricalFS!E33/[3]HistoricalFS!D33-1,0) -> -0.79011124 | F14: =IFERROR([3]HistoricalFS!F33/[3]HistoricalFS!E33-1,0) -> -3.5528471 | G14: =IFERROR([3]HistoricalFS!G33/[3]HistoricalFS!F33-1,0) -> 3.9286703 | H14: =IFERROR([3]HistoricalFS!H33/[3]HistoricalFS!G33-1,0) -> -0.82862505 | I14: =IFERROR([3]HistoricalFS!I33/[3]HistoricalFS!H33-1,0) -> 6.1952157 | J14: =IFERROR([3]HistoricalFS!J33/[3]HistoricalFS!I33-1,0) -> -0.70904365 | K14: =IFERROR([3]HistoricalFS!K33/[3]HistoricalFS!J33-1,0) -> -7.7977655 | L14: =IFERROR([3]HistoricalFS!L33/[3]HistoricalFS!K33-1,0) -> -0.39385527 | N14: =IFERROR(AVERAGE(D14:L14),0) -> -0.51597342 | O14: =IFERROR(MEDIAN(C14:L14),0) -> -0.70904365
B15: Dividend Growth | D15: =IFERROR([3]HistoricalFS!D41/[3]HistoricalFS!C41-1,0) -> -1 | E15: =IFERROR([3]HistoricalFS!E41/[3]HistoricalFS!D41-1,0) -> 0 | F15: =IFERROR([3]HistoricalFS!F41/[3]HistoricalFS!E41-1,0) -> 0 | G15: =IFERROR([3]HistoricalFS!G41/[3]HistoricalFS!F41-1,0) -> 0 | H15: =IFERROR([3]HistoricalFS!H41/[3]HistoricalFS!G41-1,0) -> 0 | I15: =IFERROR([3]HistoricalFS!I41/[3]HistoricalFS!H41-1,0) -> 0 | J15: =IFERROR([3]HistoricalFS!J41/[3]HistoricalFS!I41-1,0) -> 0 | K15: =IFERROR([3]HistoricalFS!K41/[3]HistoricalFS!J41-1,0) -> 2.0032954 | L15: =IFERROR([3]HistoricalFS!L41/[3]HistoricalFS!K41-1,0) -> -0.041110112 | N15: =IFERROR(AVERAGE(D15:L15),0) -> 0.10690947 | O15: =IFERROR(MEDIAN(C15:L15),0) -> 0
B17: Gross Margin | C17: =IFERROR([3]HistoricalFS!C13,0) -> 0.24734524 | D17: =IFERROR([3]HistoricalFS!D13,0) -> 0.23819078 | E17: =IFERROR([3]HistoricalFS!E13,0) -> 0.2164999 | F17: =IFERROR([3]HistoricalFS!F13,0) -> 0.19571167 | G17: =IFERROR([3]HistoricalFS!G13,0) -> 0.19417127 | H17: =IFERROR([3]HistoricalFS!H13,0) -> 0.21805386 | I17: =IFERROR([3]HistoricalFS!I13,0) -> 0.19807108 | J17: =IFERROR([3]HistoricalFS!J13,0) -> 0.20685018 | ... L17: =IFERROR([3]HistoricalFS!L13,0) -> 0.2248968 | N17: =IFERROR(AVERAGE(C17:L17),0) -> 0.21693584 | O17: =IFERROR(MEDIAN(C17:L17),0) -> 0.21727688
B18: EBITDA Margin | C18: =IFERROR([3]HistoricalFS!C19,0) -> 0.14061845 | D18: =IFERROR([3]HistoricalFS!D19,0) -> 0.10971269 | E18: =IFERROR([3]HistoricalFS!E19,0) -> 0.10789788 | F18: =IFERROR([3]HistoricalFS!F19,0) -> 0.081686629 | G18: =IFERROR([3]HistoricalFS!G19,0) -> 0.068898034 | H18: =IFERROR([3]HistoricalFS!H19,0) -> 0.12925584 | I18: =IFERROR([3]HistoricalFS!I19,0) -> 0.088776328 | J18: =IFERROR([3]HistoricalFS!J19,0) -> 0.091961958 | ... L18: =IFERROR([3]HistoricalFS!L19,0) -> 0.12557796 | N18: =IFERROR(AVERAGE(C18:L18),0) -> 0.10776159 | O18: =IFERROR(MEDIAN(C18:L18),0) -> 0.10880529
B19: EBIT Margin | C19: =IFERROR(([3]HistoricalFS!C18-[3]HistoricalFS!C24)/[3]HistoricalFS!C6,0) -> 0.079417028 | D19: =IFERROR(([3]HistoricalFS!D18-[3]HistoricalFS!D24)/[3]HistoricalFS!D6,0) -> 0.043322301 | E19: =IFERROR(([3]HistoricalFS!E18-[3]HistoricalFS!E24)/[3]HistoricalFS!E6,0) -> 0.033970412 | F19: =IFERROR(([3]HistoricalFS!F18-[3]HistoricalFS!F24)/[3]HistoricalFS!F6,0) -> 0.0035560233 | G19: =IFERROR(([3]HistoricalFS!G18-[3]HistoricalFS!G24)/[3]HistoricalFS!G6,0) -> -0.013170363 | H19: =IFERROR(([3]HistoricalFS!H18-[3]HistoricalFS!H24)/[3]HistoricalFS!H6,0) -> 0.034991608 | I19: =IFERROR(([3]HistoricalFS!I18-[3]HistoricalFS!I24)/[3]HistoricalFS!I6,0) -> -0.00041514993 | J19: =IFERROR(([3]HistoricalFS!J18-[3]HistoricalFS!J24)/[3]HistoricalFS!J6,0) -> 0.020104347 | ... L19: =IFERROR(([3]HistoricalFS!L18-[3]HistoricalFS!L24)/[3]HistoricalFS!L6,0) -> 0.072686749 | N19: =IFERROR(AVERAGE(C19:L19),0) -> 0.034493271 | O19: =IFERROR(MEDIAN(C19:L19),0) -> 0.03448101
B20: EBT Margin | C20: =IFERROR([3]HistoricalFS!C28,0) -> 0.061511301 | D20: =IFERROR([3]HistoricalFS!D28,0) -> 0.027608071 | E20: =IFERROR([3]HistoricalFS!E28,0) -> 0.017912164 | F20: =IFERROR([3]HistoricalFS!F28,0) -> -0.015516079 | G20: =IFERROR([3]HistoricalFS!G28,0) -> -0.04091536 | H20: =IFERROR([3]HistoricalFS!H28,0) -> 0.0025763152 | I20: =IFERROR([3]HistoricalFS!I28,0) -> -0.033856482 | J20: =IFERROR([3]HistoricalFS!J28,0) -> -0.009451885 | ... L20: =IFERROR([3]HistoricalFS!L28,0) -> 0.061126463 | N20: =IFERROR(AVERAGE(C20:L20),0) -> 0.012396721 | O20: =IFERROR(MEDIAN(C20:L20),0) -> 0.01024424
B21: Net Profit Margin | C21: =IFERROR([3]HistoricalFS!C34,0) -> 0.050432382 | D21: =IFERROR([3]HistoricalFS!D34,0) -> 0.015552749 | E21: =IFERROR([3]HistoricalFS!E34,0) -> 0.0030196143 | F21: =IFERROR([3]HistoricalFS!F34,0) -> -0.0074434057 | G21: =IFERROR([3]HistoricalFS!G34,0) -> -0.042429334 | H21: =IFERROR([3]HistoricalFS!H34,0) -> -0.0075994792 | I21: =IFERROR([3]HistoricalFS!I34,0) -> -0.049052155 | J21: =IFERROR([3]HistoricalFS!J34,0) -> -0.011486935 | ... L21: =IFERROR([3]HistoricalFS!L34,0) -> 0.037241724 | N21: =IFERROR(AVERAGE(C21:L21),0) -> 0.0050479411 | O21: =IFERROR(MEDIAN(C21:L21),0) -> -0.0022118957
B23: SalesExpense%Sales | C23: =IFERROR([3]HistoricalFS!C16,0) -> 0.10672679 | D23: =IFERROR([3]HistoricalFS!D16,0) -> 0.1284781 | E23: =IFERROR([3]HistoricalFS!E16,0) -> 0.10860202 | F23: =IFERROR([3]HistoricalFS!F16,0) -> 0.11402505 | G23: =IFERROR([3]HistoricalFS!G16,0) -> 0.12527324 | H23: =IFERROR([3]HistoricalFS!H16,0) -> 0.088798023 | I23: =IFERROR([3]HistoricalFS!I16,0) -> 0.10929475 | J23: =IFERROR([3]HistoricalFS!J16,0) -> 0.11488822 | ... L23: =IFERROR([3]HistoricalFS!L16,0) -> 0.099318846 | N23: =IFERROR(AVERAGE(C23:L23),0) -> 0.10917425 | O23: =IFERROR(MEDIAN(C23:L23),0) -> 0.10894839
B24: Depreciation%Sales | C24: =IFERROR([3]HistoricalFS!C25,0) -> 0.061201426 | D24: =IFERROR([3]HistoricalFS!D25,0) -> 0.066390387 | E24: =IFERROR([3]HistoricalFS!E25,0) -> 0.073927472 | F24: =IFERROR([3]HistoricalFS!F25,0) -> 0.078130605 | G24: =IFERROR([3]HistoricalFS!G25,0) -> 0.082068398 | H24: =IFERROR([3]HistoricalFS!H25,0) -> 0.094264231 | I24: =IFERROR([3]HistoricalFS!I25,0) -> 0.089191478 | J24: =IFERROR([3]HistoricalFS!J25,0) -> 0.071857611 | ... L24: =IFERROR([3]HistoricalFS!L25,0) -> 0.052891209 | N24: =IFERROR(AVERAGE(C24:L24),0) -> 0.073268318 | O24: =IFERROR(MEDIAN(C24:L24),0) -> 0.072892542
B25: OperatingIncome%Sales | C25: =C19 -> 0.079417028 | D25: =D19 -> 0.043322301 | E25: =E19 -> 0.033970412 | F25: =F19 -> 0.0035560233 | G25: =G19 -> -0.013170363 | H25: =H19 -> 0.034991608 | I25: =I19 -> -0.00041514993 | J25: =J19 -> 0.020104347 | ... L25: =L19 -> 0.072686749 | N25: =IFERROR(AVERAGE(C25:L25),0) -> 0.034493271 | O25: =IFERROR(MEDIAN(C25:L25),0) -> 0.03448101
B27: Return on Capital Employed | C27: =IFERROR(([3]HistoricalFS!C18-[3]HistoricalFS!C24)/(SUM([3]HistoricalFS!C47:C49)),0) -> 0.1462081 | D27: =IFERROR(([3]HistoricalFS!D18-[3]HistoricalFS!D24)/(SUM([3]HistoricalFS!D47:D49)),0) -> 0.085490986 | E27: =IFERROR(([3]HistoricalFS!E18-[3]HistoricalFS!E24)/(SUM([3]HistoricalFS!E47:E49)),0) -> 0.053716114 | F27: =IFERROR(([3]HistoricalFS!F18-[3]HistoricalFS!F24)/(SUM([3]HistoricalFS!F47:F49)),0) -> 0.0064542734 | G27: =IFERROR(([3]HistoricalFS!G18-[3]HistoricalFS!G24)/(SUM([3]HistoricalFS!G47:G49)),0) -> -0.018302178 | H27: =IFERROR(([3]HistoricalFS!H18-[3]HistoricalFS!H24)/(SUM([3]HistoricalFS!H47:H49)),0) -> 0.044284325 | I27: =IFERROR(([3]HistoricalFS!I18-[3]HistoricalFS!I24)/(SUM([3]HistoricalFS!I47:I49)),0) -> -0.00060520306 | J27: =IFERROR(([3]HistoricalFS!J18-[3]HistoricalFS!J24)/(SUM([3]HistoricalFS!J47:J49)),0) -> 0.038762956 | ... L27: =IFERROR(([3]HistoricalFS!L18-[3]HistoricalFS!L24)/(SUM([3]HistoricalFS!L47:L49)),0) -> 0.17028623 | N27: =IFERROR(AVERAGE(C27:L27),0) -> 0.068544162 | O27: =IFERROR(MEDIAN(C27:L27),0) -> 0.049000219
B28: Retaind Earnings% | C28: =IFERROR([3]HistoricalFS!C44,0) -> 0.99506766 | D28: =IFERROR([3]HistoricalFS!D44,0) -> 1 | E28: =IFERROR([3]HistoricalFS!E44,0) -> 1 | F28: =IFERROR([3]HistoricalFS!F44,0) -> 0 | G28: =IFERROR([3]HistoricalFS!G44,0) -> 0 | H28: =IFERROR([3]HistoricalFS!H44,0) -> 0 | I28: =IFERROR([3]HistoricalFS!I44,0) -> 0 | J28: =IFERROR([3]HistoricalFS!J44,0) -> 0 | ... L28: =IFERROR([3]HistoricalFS!L44,0) -> 0.86516031 | N28: =IFERROR(AVERAGE(C28:L28),0) -> 0.47750531 | O28: =IFERROR(MEDIAN(C28:L28),0) -> 0.43258015
B29: Return on Equity% | C29: =IFERROR([3]HistoricalFS!C33/SUM([3]HistoricalFS!C47:C48),0) -> 0.17441317 | D29: =IFERROR([3]HistoricalFS!D33/SUM([3]HistoricalFS!D47:D48),0) -> 0.07224119 | E29: =IFERROR([3]HistoricalFS!E33/SUM([3]HistoricalFS!E47:E48),0) -> 0.0092254981 | F29: =IFERROR([3]HistoricalFS!F33/SUM([3]HistoricalFS!F47:F48),0) -> -0.037345737 | G29: =IFERROR([3]HistoricalFS!G33/SUM([3]HistoricalFS!G47:G48),0) -> -0.17560555 | H29: =IFERROR([3]HistoricalFS!H33/SUM([3]HistoricalFS!H47:H48),0) -> -0.034360592 | I29: =IFERROR([3]HistoricalFS!I33/SUM([3]HistoricalFS!I47:I48),0) -> -0.30651638 | J29: =IFERROR([3]HistoricalFS!J33/SUM([3]HistoricalFS!J47:J48),0) -> -0.087686298 | ... L29: =IFERROR([3]HistoricalFS!L33/SUM([3]HistoricalFS!L47:L48),0) -> 0.14098877 | N29: =IFERROR(AVERAGE(C29:L29),0) -> 0.0073484502 | O29: =IFERROR(MEDIAN(C29:L29),0) -> -0.012567547
B30: Self Sustained Growth Rate | C30: =IFERROR(C28*C29,0) -> 0.1735529 | D30: =IFERROR(D28*D29,0) -> 0.07224119 | E30: =IFERROR(E28*E29,0) -> 0.0092254981 | F30: =IFERROR(F28*F29,0) -> 0 | G30: =IFERROR(G28*G29,0) -> 0 | H30: =IFERROR(H28*H29,0) -> 0 | I30: =IFERROR(I28*I29,0) -> 0 | J30: =IFERROR(J28*J29,0) -> 0 | ... L30: =IFERROR(L28*L29,0) -> 0.12197789 | N30: =IFERROR(AVERAGE(C30:L30),0) -> 0.066803118 | O30: =IFERROR(MEDIAN(C30:L30),0) -> 0.004612749
B31: Interest Coverage Ration | C31: =IFERROR((([3]HistoricalFS!C18-[3]HistoricalFS!C24)/[3]HistoricalFS!C21),0) -> 4.4352864 | D31: =IFERROR((([3]HistoricalFS!D18-[3]HistoricalFS!D24)/[3]HistoricalFS!D21),0) -> 2.7568835 | E31: =IFERROR((([3]HistoricalFS!E18-[3]HistoricalFS!E24)/[3]HistoricalFS!E21),0) -> 2.1154494 | F31: =IFERROR((([3]HistoricalFS!F18-[3]HistoricalFS!F24)/[3]HistoricalFS!F21),0) -> 0.18645157 | G31: =IFERROR((([3]HistoricalFS!G18-[3]HistoricalFS!G24)/[3]HistoricalFS!G21),0) -> -0.47469327 | H31: =IFERROR((([3]HistoricalFS!H18-[3]HistoricalFS!H24)/[3]HistoricalFS!H21),0) -> 1.0794784 | I31: =IFERROR((([3]HistoricalFS!I18-[3]HistoricalFS!I24)/[3]HistoricalFS!I21),0) -> -0.012414276 | J31: =IFERROR((([3]HistoricalFS!J18-[3]HistoricalFS!J24)/[3]HistoricalFS!J21),0) -> 0.6802067 | ... L31: =IFERROR((([3]HistoricalFS!L18-[3]HistoricalFS!L24)/[3]HistoricalFS!L21),0) -> 6.2876254 | N31: =IFERROR(AVERAGE(C31:L31),0) -> 2.1081796 | O31: =IFERROR(MEDIAN(C31:L31),0) -> 1.5974639
B33: Debtor Turnover Ratio | C33: =IFERROR([3]HistoricalFS!C6/[3]HistoricalFS!C59,0) -> 20.119918 | D33: =IFERROR([3]HistoricalFS!D6/[3]HistoricalFS!D59,0) -> 19.160353 | E33: =IFERROR([3]HistoricalFS!E6/[3]HistoricalFS!E59,0) -> 14.655712 | F33: =IFERROR([3]HistoricalFS!F6/[3]HistoricalFS!F59,0) -> 15.894699 | G33: =IFERROR([3]HistoricalFS!G6/[3]HistoricalFS!G59,0) -> 23.366617 | H33: =IFERROR([3]HistoricalFS!H6/[3]HistoricalFS!H59,0) -> 19.701331 | I33: =IFERROR([3]HistoricalFS!I6/[3]HistoricalFS!I59,0) -> 22.379918 | J33: =IFERROR([3]HistoricalFS!J6/[3]HistoricalFS!J59,0) -> 21.982948 | ... L33: =IFERROR([3]HistoricalFS!L6/[3]HistoricalFS!L59,0) -> 33.189538 | N33: =IFERROR(AVERAGE(C33:L33),0) -> 21.605368 | O33: =IFERROR(MEDIAN(C33:L33),0) -> 21.051433
B34: Creditor Turnover Ratio | C34: =IFERROR([3]HistoricalFS!C6/[3]HistoricalFS!C50,0) -> 2.3769604 | D34: =IFERROR([3]HistoricalFS!D6/[3]HistoricalFS!D50,0) -> 1.9842808 | E34: =IFERROR([3]HistoricalFS!E6/[3]HistoricalFS!E50,0) -> 2.041478 | F34: =IFERROR([3]HistoricalFS!F6/[3]HistoricalFS!F50,0) -> 2.1667848 | G34: =IFERROR([3]HistoricalFS!G6/[3]HistoricalFS!G50,0) -> 1.9731057 | H34: =IFERROR([3]HistoricalFS!H6/[3]HistoricalFS!H50,0) -> 1.7323685 | I34: =IFERROR([3]HistoricalFS!I6/[3]HistoricalFS!I50,0) -> 2.0170312 | J34: =IFERROR([3]HistoricalFS!J6/[3]HistoricalFS!J50,0) -> 2.2286057 | ... L34: =IFERROR([3]HistoricalFS!L6/[3]HistoricalFS!L50,0) -> 2.3228767 | N34: =IFERROR(AVERAGE(C34:L34),0) -> 2.1290872 | O34: =IFERROR(MEDIAN(C34:L34),0) -> 2.1041314
B35: Inventory Turnover ratio | C35: =IFERROR([3]HistoricalFS!C6/[3]HistoricalFS!C60,0) -> 8.3613381 | D35: =IFERROR([3]HistoricalFS!D6/[3]HistoricalFS!D60,0) -> 7.6867643 | E35: =IFERROR([3]HistoricalFS!E6/[3]HistoricalFS!E60,0) -> 6.9190052 | F35: =IFERROR([3]HistoricalFS!F6/[3]HistoricalFS!F60,0) -> 7.7392856 | G35: =IFERROR([3]HistoricalFS!G6/[3]HistoricalFS!G60,0) -> 6.9698269 | H35: =IFERROR([3]HistoricalFS!H6/[3]HistoricalFS!H60,0) -> 6.9217099 | I35: =IFERROR([3]HistoricalFS!I6/[3]HistoricalFS!I60,0) -> 7.9015588 | J35: =IFERROR([3]HistoricalFS!J6/[3]HistoricalFS!J60,0) -> 8.4888642 | ... L35: =IFERROR([3]HistoricalFS!L6/[3]HistoricalFS!L60,0) -> 9.3019738 | N35: =IFERROR(AVERAGE(C35:L35),0) -> 7.937244 | O35: =IFERROR(MEDIAN(C35:L35),0) -> 7.8204222
B36: Fixed Asset Turnover Ratio | C36: =IFERROR([3]HistoricalFS!C6/[3]HistoricalFS!C53,0) -> 2.5463128 | D36: =IFERROR([3]HistoricalFS!D6/[3]HistoricalFS!D53,0) -> 2.8109343 | E36: =IFERROR([3]HistoricalFS!E6/[3]HistoricalFS!E53,0) -> 2.4012949 | F36: =IFERROR([3]HistoricalFS!F6/[3]HistoricalFS!F53,0) -> 2.714432 | G36: =IFERROR([3]HistoricalFS!G6/[3]HistoricalFS!G53,0) -> 2.0539206 | H36: =IFERROR([3]HistoricalFS!H6/[3]HistoricalFS!H53,0) -> 1.8008727 | I36: =IFERROR([3]HistoricalFS!I6/[3]HistoricalFS!I53,0) -> 2.0053489 | J36: =IFERROR([3]HistoricalFS!J6/[3]HistoricalFS!J53,0) -> 2.6193792 | ... L36: =IFERROR([3]HistoricalFS!L6/[3]HistoricalFS!L53,0) -> 3.800401 | N36: =IFERROR(AVERAGE(C36:L36),0) -> 2.6331377 | O36: =IFERROR(MEDIAN(C36:L36),0) -> 2.582846
B37: Capital Turnover Ratio | C37: =IFERROR([3]HistoricalFS!C6/SUM([3]HistoricalFS!C47:C48),0) -> 3.4583567 | D37: =IFERROR([3]HistoricalFS!D6/SUM([3]HistoricalFS!D47:D48),0) -> 4.6449144 | E37: =IFERROR([3]HistoricalFS!E6/SUM([3]HistoricalFS!E47:E48),0) -> 3.0551909 | F37: =IFERROR([3]HistoricalFS!F6/SUM([3]HistoricalFS!F47:F48),0) -> 5.0172916 | G37: =IFERROR([3]HistoricalFS!G6/SUM([3]HistoricalFS!G47:G48),0) -> 4.138777 | H37: =IFERROR([3]HistoricalFS!H6/SUM([3]HistoricalFS!H47:H48),0) -> 4.5214404 | I37: =IFERROR([3]HistoricalFS!I6/SUM([3]HistoricalFS!I47:I48),0) -> 6.2487853 | J37: =IFERROR([3]HistoricalFS!J6/SUM([3]HistoricalFS!J47:J48),0) -> 7.6335681 | ... L37: =IFERROR([3]HistoricalFS!L6/SUM([3]HistoricalFS!L47:L48),0) -> 3.7857746 | N37: =IFERROR(AVERAGE(C37:L37),0) -> 4.76151 | O37: =IFERROR(MEDIAN(C37:L37),0) -> 4.5831774
B39: (in days)
B40: Debtor Days | C40: =IFERROR(365/C33,0) -> 18.141227 | D40: =IFERROR(365/D33,0) -> 19.049753 | E40: =IFERROR(365/E33,0) -> 24.904965 | F40: =IFERROR(365/F33,0) -> 22.963631 | G40: =IFERROR(365/G33,0) -> 15.620575 | H40: =IFERROR(365/H33,0) -> 18.526667 | I40: =IFERROR(365/I33,0) -> 16.309265 | J40: =IFERROR(365/J33,0) -> 16.603779 | ... L40: =IFERROR(365/L33,0) -> 10.997441 | N40: =IFERROR(AVERAGE(C40:L40),0) -> 17.737364 | O40: =IFERROR(MEDIAN(C40:L40),0) -> 17.372503
B41: Payable Days | C41: =IFERROR(365/C34,0) -> 153.55746 | D41: =IFERROR(365/D34,0) -> 183.94574 | E41: =IFERROR(365/E34,0) -> 178.79203 | F41: =IFERROR(365/F34,0) -> 168.45236 | G41: =IFERROR(365/G34,0) -> 184.98755 | H41: =IFERROR(365/H34,0) -> 210.69421 | I41: =IFERROR(365/I34,0) -> 180.95902 | J41: =IFERROR(365/J34,0) -> 163.77953 | ... L41: =IFERROR(365/L34,0) -> 157.13275 | N41: =IFERROR(AVERAGE(C41:L41),0) -> 173.14397 | O41: =IFERROR(MEDIAN(C41:L41),0) -> 173.62219
B42: Inventory Days | C42: =IFERROR(365/C35,0) -> 43.6533 | D42: =IFERROR(365/D35,0) -> 47.484219 | E42: =IFERROR(365/E35,0) -> 52.753249 | F42: =IFERROR(365/F35,0) -> 47.161976 | G42: =IFERROR(365/G35,0) -> 52.368589 | H42: =IFERROR(365/H35,0) -> 52.732635 | I42: =IFERROR(365/I35,0) -> 46.193417 | J42: =IFERROR(365/J35,0) -> 42.997507 | ... L42: =IFERROR(365/L35,0) -> 39.238984 | N42: =IFERROR(AVERAGE(C42:L42),0) -> 46.477276 | O42: =IFERROR(MEDIAN(C42:L42),0) -> 46.677696
B43: Cash Conversion Cycle | C43: =SUM(C40,C42)-C41 -> -91.762933 | D43: =SUM(D40,D42)-D41 -> -117.41177 | E43: =SUM(E40,E42)-E41 -> -101.13382 | F43: =SUM(F40,F42)-F41 -> -98.326751 | G43: =SUM(G40,G42)-G41 -> -116.99839 | H43: =SUM(H40,H42)-H41 -> -139.4349 | I43: =SUM(I40,I42)-I41 -> -118.45634 | J43: =SUM(J40,J42)-J41 -> -104.17824 | ... L43: =SUM(L40,L42)-L41 -> -106.89633 | N43: =IFERROR(AVERAGE(C43:L43),0) -> -108.92933 | O43: =IFERROR(MEDIAN(C43:L43),0) -> -105.53729
B45: CFO/Sales | C45: =IFERROR([3]HistoricalFS!C70/[3]HistoricalFS!C6,0) -> -0.13438744 | D45: =IFERROR([3]HistoricalFS!D70/[3]HistoricalFS!D6,0) -> -0.14672784 | E45: =IFERROR([3]HistoricalFS!E70/[3]HistoricalFS!E6,0) -> -0.086225686 | F45: =IFERROR([3]HistoricalFS!F70/[3]HistoricalFS!F6,0) -> -0.069146786 | G45: =IFERROR([3]HistoricalFS!G70/[3]HistoricalFS!G6,0) -> -0.12684264 | H45: =IFERROR([3]HistoricalFS!H70/[3]HistoricalFS!H6,0) -> -0.10277438 | I45: =IFERROR([3]HistoricalFS!I70/[3]HistoricalFS!I6,0) -> -0.015958349 | J45: =IFERROR([3]HistoricalFS!J70/[3]HistoricalFS!J6,0) -> -0.044562549 | ... L45: =IFERROR([3]HistoricalFS!L70/[3]HistoricalFS!L6,0) -> -0.11367425 | N45: =IFERROR(AVERAGE(C45:L45),0) -> -0.089278877 | O45: =IFERROR(MEDIAN(C45:L45),0) -> -0.094500032
B46: CFO/Total Assets | C46: =IFERROR([3]HistoricalFS!C70/[3]HistoricalFS!C64,0) -> -0.13942293 | D46: =IFERROR([3]HistoricalFS!D70/[3]HistoricalFS!D64,0) -> -0.14517334 | E46: =IFERROR([3]HistoricalFS!E70/[3]HistoricalFS!E64,0) -> -0.076833036 | F46: =IFERROR([3]HistoricalFS!F70/[3]HistoricalFS!F64,0) -> -0.068295164 | G46: =IFERROR([3]HistoricalFS!G70/[3]HistoricalFS!G64,0) -> -0.10342499 | H46: =IFERROR([3]HistoricalFS!H70/[3]HistoricalFS!H64,0) -> -0.075160309 | I46: =IFERROR([3]HistoricalFS!I70/[3]HistoricalFS!I64,0) -> -0.013504041 | J46: =IFERROR([3]HistoricalFS!J70/[3]HistoricalFS!J64,0) -> -0.046066172 | ... L46: =IFERROR([3]HistoricalFS!L70/[3]HistoricalFS!L64,0) -> -0.13258775 | N46: =IFERROR(AVERAGE(C46:L46),0) -> -0.08621178 | O46: =IFERROR(MEDIAN(C46:L46),0) -> -0.075996672
B47: CFO/Total Debts | C47: =IFERROR([3]HistoricalFS!C70/[3]HistoricalFS!C49,0) -> -0.52903577 | D47: =IFERROR([3]HistoricalFS!D70/[3]HistoricalFS!D49,0) -> -0.50342743 | E47: =IFERROR([3]HistoricalFS!E70/[3]HistoricalFS!E49,0) -> -0.28261953 | F47: =IFERROR([3]HistoricalFS!F70/[3]HistoricalFS!F49,0) -> -0.19663766 | G47: =IFERROR([3]HistoricalFS!G70/[3]HistoricalFS!G49,0) -> -0.26536723 | H47: =IFERROR([3]HistoricalFS!H70/[3]HistoricalFS!H49,0) -> -0.18062617 | I47: =IFERROR([3]HistoricalFS!I70/[3]HistoricalFS!I49,0) -> -0.030342707 | J47: =IFERROR([3]HistoricalFS!J70/[3]HistoricalFS!J49,0) -> -0.11495619 | ... L47: =IFERROR([3]HistoricalFS!L70/[3]HistoricalFS!L49,0) -> -0.69865809 | N47: =IFERROR(AVERAGE(C47:L47),0) -> -0.30140533 | O47: =IFERROR(MEDIAN(C47:L47),0) -> -0.23887488

Sheet Forecasting
B2: TATA MOTORS LTD
B3: ( TATA MOTORS LTD | BSE Code : 500570 )
B4: INR 716.00 (as on 05.10.2025)
B5: 52 Week ( High - INR 948.45 & Low - 535.75)
B8: ='[4]Data Sheet'!$B$1&" - "&'[4]Data Sheet'!A17&" Forecasting" -> TATA MOTORS LTD - Sales Forecasting | G8: ='[4]Data Sheet'!$B$1&" - "&[4]HistoricalFS!B23&" Forecasting" -> TATA MOTORS LTD - EBITDA Forecasting | L8: ='[4]Data Sheet'!$B$1&" - "&[4]HistoricalFS!B43&" Forecasting" -> TATA MOTORS LTD - Earning per Share Forecasting
B9: Year weight | C9: Year | D9: Sales | E9: Sales Growth | G9: Year weight | H9: Year | I9: EBITDA | J9: Sales Growth | L9: Year weight | M9: Year | N9: EBITDA | O9: Sales Growth
B10: 1 | C10: ='[3]Data Sheet'!B16 -> 42460 | D10: 273045.6 | G10: 1 | H10: ='[3]Data Sheet'!B16 -> 42460 | I10: 36204.22 | L10: 1 | M10: ='[3]Data Sheet'!G16 -> 44286 | N10: 47.691141
B11: =B10+1 -> 2 | C11: =C10+365 -> 42825 | D11: 269692.51 | E11: =D11/D10-1 -> -0.01228033 | G11: =G10+1 -> 2 | H11: =H10+365 -> 42825 | I11: 32848.59 | J11: =I11/I10-1 -> -0.092686156 | L11: =L10+1 -> 2 | M11: =M10+365 -> 44651 | N11: 14.527778 | O11: =N11/N10-1 -> -0.69537785
B12: =B11+1 -> 3 | C12: =C11+365 -> 43190 | D12: 291550.48 | E12: =D12/D11-1 -> 0.081047746 | G12: =G11+1 -> 3 | H12: =H11+365 -> 43190 | I12: 39566.22 | J12: =I12/I11-1 -> 0.20450284 | L12: =L11+1 -> 3 | M12: =M11+365 -> 45016 | N12: 3.0491116 | O12: =N12/N11-1 -> -0.79011851
B13: =B12+1 -> 4 | C13: =C12+365 -> 43555 | D13: 301938.4 | E13: =D13/D12-1 -> 0.035629919 | G13: =G12+1 -> 4 | H13: =H12+365 -> 43555 | I13: -1914.45 | J13: =I13/I12-1 -> -1.048386 | L13: =L12+1 -> 4 | M13: =M12+365 -> 45381 | N13: -7.7839158 | O13: =N13/N12-1 -> -3.5528471
B14: =B13+1 -> 5 | C14: =C13+365 -> 43920 | D14: 261067.97 | E14: =D14/D13-1 -> -0.13536016 | G14: =G13+1 -> 5 | H14: =H13+365 -> 43920 | I14: 16993.16 | J14: =I14/I13-1 -> -9.8762621 | L14: =L13+1 -> 5 | M14: =M13+365 -> 45746 | N14: -38.364354 | O14: =N14/N13-1 -> 3.9286703
B15: =B14+1 -> 6 | C15: =C14+365 -> 44285 | D15: 249794.75 | E15: =D15/D14-1 -> -0.043181168 | G15: =G14+1 -> 6 | H15: =H14+365 -> 44285 | I15: 20734.35 | J15: =I15/I14-1 -> 0.22015858 | L15: =L14+1 -> 6 | M15: =M14+365 -> 46111 | N15: -6.1453869 | O15: =N15/N14-1 -> -0.83981519
B16: =B15+1 -> 7 | C16: =C15+365 -> 44650 | D16: 278453.62 | E16: =D16/D15-1 -> 0.11472967 | G16: =G15+1 -> 7 | H16: =H15+365 -> 44650 | I16: 26937.37 | J16: =I16/I15-1 -> 0.29916636 | L16: =L15+1 -> 7 | M16: =M15+365 -> 46476 | N16: -41.137096 | O16: =N16/N15-1 -> 5.6939799
B17: =B16+1 -> 8 | C17: =C16+365 -> 45015 | D17: 345966.97 | E17: =D17/D16-1 -> 0.24245815 | G17: =G16+1 -> 8 | H17: =H16+365 -> 45015 | I17: 38204.19 | J17: =I17/I16-1 -> 0.41825984 | L17: =L16+1 -> 8 | M17: =M16+365 -> 46841 | N17: -11.967657 | O17: =N17/N16-1 -> -0.7090787
B18: =B17+1 -> 9 | C18: =C17+365 -> 45380 | D18: 434016 | E18: =D18/D17-1 -> 0.25450126 | G18: =G17+1 -> 9 | H18: =H17+365 -> 45380 | I18: 62208 | J18: =I18/I17-1 -> 0.62830307 | L18: =L17+1 -> 9 | M18: =M17+365 -> 47206 | N18: 81.338632 | O18: =N18/N17-1 -> -7.7965375
B19: =B18+1 -> 10 | C19: =C18+365 -> 45745 | D19: 439695 | E19: =D19/D18-1 -> 0.013084771 | G19: =G18+1 -> 10 | H19: =H18+365 -> 45745 | I19: 66671 | J19: =I19/I18-1 -> 0.071743184 | L19: =L18+1 -> 10 | M19: =M18+365 -> 47571 | N19: 49.267383 | O19: =N19/N18-1 -> -0.39429295
B20: =B19+1 -> 11 | C20: =C19+365 -> 46110 | D20: =FORECAST(B20,$D$10:$D$19,$B$10:$B$19) -> 409204.26 | E20: =D20/D19-1 -> -0.069345204 | G20: =G19+1 -> 11 | H20: =H19+365 -> 46110 | I20: =FORECAST($G$20,I10:I19,$G$10:$G$19) -> 52618.711 | J20: =I20/I19-1 -> -0.21077063 | L20: =L19+1 -> 11 | M20: =M19+365 -> 47936 | N20: =FORECAST($L$20,N10:N19,$L$10:$L$19) -> 20.345488 | O20: =N20/N19-1 -> -0.58703939
B21: =B20+1 -> 12 | C21: =C20+365 -> 46475 | D21: =FORECAST(B21,$D$10:$D$19,$B$10:$B$19) -> 426419.19 | E21: =D21/D20-1 -> 0.04206929 | G21: =G20+1 -> 12 | H21: =H20+365 -> 46475 | I21: =FORECAST($G$20,I11:I20,$G$10:$G$19) -> 60757.145 | J21: =I21/I20-1 -> 0.15466804 | L21: =L20+1 -> 12 | M21: =M20+365 -> 48301 | N21: =FORECAST($L$20,N11:N20,$L$10:$L$19) -> 35.169612 | O21: =N21/N20-1 -> 0.72861972
B22: =B21+1 -> 13 | C22: =C21+365 -> 46840 | D22: =FORECAST(B22,$D$10:$D$19,$B$10:$B$19) -> 443634.13 | E22: =D22/D21-1 -> 0.040370915 | G22: =G21+1 -> 13 | H22: =H21+365 -> 46840 | I22: =FORECAST($G$20,I12:I21,$G$10:$G$19) -> 70161.817 | J22: =I22/I21-1 -> 0.15479122 | L22: =L21+1 -> 13 | M22: =M21+365 -> 48666 | N22: =FORECAST($L$20,N12:N21,$L$10:$L$19) -> 48.902865 | O22: =N22/N21-1 -> 0.39048635
B23: =B22+1 -> 14 | C23: =C22+365 -> 47205 | D23: =FORECAST(B23,$D$10:$D$19,$B$10:$B$19) -> 460849.06 | E23: =D23/D22-1 -> 0.038804348 | G23: =G22+1 -> 14 | H23: =H22+365 -> 47205 | I23: =FORECAST($G$20,I13:I22,$G$10:$G$19) -> 83259.156 | J23: =I23/I22-1 -> 0.18667332 | L23: =L22+1 -> 14 | M23: =M22+365 -> 49031 | N23: =FORECAST($L$20,N13:N22,$L$10:$L$19) -> 63.69232 | O23: =N23/N22-1 -> 0.30242512
B24: =B23+1 -> 15 | C24: =C23+365 -> 47570 | D24: =FORECAST(B24,$D$10:$D$19,$B$10:$B$19) -> 478063.99 | E24: =D24/D23-1 -> 0.037354818 | G24: =G23+1 -> 15 | H24: =H23+365 -> 47570 | I24: =FORECAST($G$20,I14:I23,$G$10:$G$19) -> 88494.212 | J24: =I24/I23-1 -> 0.062876643 | L24: =L23+1 -> 15 | M24: =M23+365 -> 49396 | N24: =FORECAST($L$20,N14:N23,$L$10:$L$19) -> 78.451833 | O24: =N24/N23-1 -> 0.23173143

Sheet Common Size Statement
B2: TATA MOTORS LTD
B3: ( TATA MOTORS LTD | BSE Code : 500570 )
B4: INR 716.00 (as on 05.10.2025)
B5: 52 Week ( High - INR 948.45 & Low - 535.75)
B8: ="Common Sixe Income Statement"& " "&" - "&'[3]Data Sheet'!$B$1 -> Common Sixe Income Statement - TATA MOTORS LTD
B10: Particulars | C10: ='[3]Data Sheet'!B$16 -> 42460 | D10: ='[3]Data Sheet'!C$16 -> 42825 | E10: ='[3]Data Sheet'!D$16 -> 43190 | F10: ='[3]Data Sheet'!E$16 -> 43555 | G10: ='[3]Data Sheet'!F$16 -> 43921 | H10: ='[3]Data Sheet'!G$16 -> 44286 | I10: ='[3]Data Sheet'!H$16 -> 44651 | J10: ='[3]Data Sheet'!I$16 -> 45016 | ... L10: ='[3]Data Sheet'!K$16 -> 45747
B12: ='[3]Data Sheet'!A17 -> Sales | C12: ='[3]Data Sheet'!B17/'[3]Data Sheet'!B$17 -> 1 | D12: ='[3]Data Sheet'!C17/'[3]Data Sheet'!C$17 -> 1 | E12: ='[3]Data Sheet'!D17/'[3]Data Sheet'!D$17 -> 1 | F12: ='[3]Data Sheet'!E17/'[3]Data Sheet'!E$17 -> 1 | G12: ='[3]Data Sheet'!F17/'[3]Data Sheet'!F$17 -> 1 | H12: ='[3]Data Sheet'!G17/'[3]Data Sheet'!G$17 -> 1 | I12: ='[3]Data Sheet'!H17/'[3]Data Sheet'!H$17 -> 1 | J12: ='[3]Data Sheet'!I17/'[3]Data Sheet'!I$17 -> 1 | ... L12: ='[3]Data Sheet'!K17/'[3]Data Sheet'!K$17 -> 1
B13: ='[3]Data Sheet'!A18 -> Raw Material Cost | C13: ='[3]Data Sheet'!B18/'[3]Data Sheet'!B$17 -> 0.60844786 | D13: ='[3]Data Sheet'!C18/'[3]Data Sheet'!C$17 -> 0.64256171 | E13: ='[3]Data Sheet'!D18/'[3]Data Sheet'!D$17 -> 0.64447357 | F13: ='[3]Data Sheet'!E18/'[3]Data Sheet'!E$17 -> 0.64340246 | G13: ='[3]Data Sheet'!F18/'[3]Data Sheet'!F$17 -> 0.63163559 | H13: ='[3]Data Sheet'!G18/'[3]Data Sheet'!G$17 -> 0.6149343 | I13: ='[3]Data Sheet'!H18/'[3]Data Sheet'!H$17 -> 0.64389657 | J13: ='[3]Data Sheet'!I18/'[3]Data Sheet'!I$17 -> 0.66842005 | ... L13: ='[3]Data Sheet'!K18/'[3]Data Sheet'!K$17 -> 0.611674
B14: ='[3]Data Sheet'!A19 -> Change in Inventory | C14: ='[3]Data Sheet'!B19/'[3]Data Sheet'!B$17 -> 0.010075204 | D14: ='[3]Data Sheet'!C19/'[3]Data Sheet'!C$17 -> 0.027438359 | E14: ='[3]Data Sheet'!D19/'[3]Data Sheet'!D$17 -> 0.007019642 | F14: ='[3]Data Sheet'!E19/'[3]Data Sheet'!E$17 -> -0.0068003275 | G14: ='[3]Data Sheet'!F19/'[3]Data Sheet'!F$17 -> -0.008546395 | H14: ='[3]Data Sheet'!G19/'[3]Data Sheet'!G$17 -> -0.018752035 | I14: ='[3]Data Sheet'!H19/'[3]Data Sheet'!H$17 -> -0.0057118668 | J14: ='[3]Data Sheet'!I19/'[3]Data Sheet'!I$17 -> 0.01382103 | ... L14: ='[3]Data Sheet'!K19/'[3]Data Sheet'!K$17 -> -0.0064499255
B15: ='[3]Data Sheet'!A20 -> Power and Fuel | C15: ='[3]Data Sheet'!B20/'[3]Data Sheet'!B$17 -> 0.0041884213 | D15: ='[3]Data Sheet'!C20/'[3]Data Sheet'!C$17 -> 0.0043005273 | E15: ='[3]Data Sheet'!D20/'[3]Data Sheet'!D$17 -> 0.004486633 | F15: ='[3]Data Sheet'!E20/'[3]Data Sheet'!E$17 -> 0.0052524952 | G15: ='[3]Data Sheet'!F20/'[3]Data Sheet'!F$17 -> 0.0048452899 | H15: ='[3]Data Sheet'!G20/'[3]Data Sheet'!G$17 -> 0.0044551377 | I15: ='[3]Data Sheet'!H20/'[3]Data Sheet'!H$17 -> 0.0078228109 | J15: ='[3]Data Sheet'!I20/'[3]Data Sheet'!I$17 -> 0.007264653 | ... L15: ='[3]Data Sheet'!K20/'[3]Data Sheet'!K$17 -> 0.0055561241
B16: ='[3]Data Sheet'!A21 -> Other Mfr. Exp | C16: ='[3]Data Sheet'!B21/'[3]Data Sheet'!B$17 -> 0.044320546 | D16: ='[3]Data Sheet'!C21/'[3]Data Sheet'!C$17 -> 0.037329068 | E16: ='[3]Data Sheet'!D21/'[3]Data Sheet'!D$17 -> 0.037632111 | F16: ='[3]Data Sheet'!E21/'[3]Data Sheet'!E$17 -> 0.038731543 | G16: ='[3]Data Sheet'!F21/'[3]Data Sheet'!F$17 -> 0.044208832 | H16: ='[3]Data Sheet'!G21/'[3]Data Sheet'!G$17 -> 0.033119871 | I16: ='[3]Data Sheet'!H21/'[3]Data Sheet'!H$17 -> 0.033856195 | J16: ='[3]Data Sheet'!I21/'[3]Data Sheet'!I$17 -> 0.03400894 | ... L16: ='[3]Data Sheet'!K21/'[3]Data Sheet'!K$17 -> 0.042786477
B17: ='[3]Data Sheet'!A22 -> Employee Cost | C17: ='[3]Data Sheet'!B22/'[3]Data Sheet'!B$17 -> 0.10577314 | D17: ='[3]Data Sheet'!C22/'[3]Data Sheet'!C$17 -> 0.10505627 | E17: ='[3]Data Sheet'!D22/'[3]Data Sheet'!D$17 -> 0.10392742 | F17: ='[3]Data Sheet'!E22/'[3]Data Sheet'!E$17 -> 0.1101015 | G17: ='[3]Data Sheet'!F22/'[3]Data Sheet'!F$17 -> 0.11659263 | H17: ='[3]Data Sheet'!G22/'[3]Data Sheet'!G$17 -> 0.11068479 | I17: ='[3]Data Sheet'!H22/'[3]Data Sheet'!H$17 -> 0.11064148 | J17: ='[3]Data Sheet'!I22/'[3]Data Sheet'!I$17 -> 0.097277205 | ... L17: ='[3]Data Sheet'!K22/'[3]Data Sheet'!K$17 -> 0.10863667
B18: ='[3]Data Sheet'!A23 -> Selling and admin | C18: ='[3]Data Sheet'!B23/'[3]Data Sheet'!B$17 -> 0.080542957 | D18: ='[3]Data Sheet'!C23/'[3]Data Sheet'!C$17 -> 0.11138381 | E18: ='[3]Data Sheet'!D23/'[3]Data Sheet'!D$17 -> 0.10634378 | F18: ='[3]Data Sheet'!E23/'[3]Data Sheet'!E$17 -> 0.10836581 | G18: ='[3]Data Sheet'!F23/'[3]Data Sheet'!F$17 -> 0.11203335 | H18: ='[3]Data Sheet'!G23/'[3]Data Sheet'!G$17 -> 0.092138806 | I18: ='[3]Data Sheet'!H23/'[3]Data Sheet'!H$17 -> 0.10488425 | J18: ='[3]Data Sheet'!I23/'[3]Data Sheet'!I$17 -> 0.10070091 | ... L18: ='[3]Data Sheet'!K23/'[3]Data Sheet'!K$17 -> 0.10711743
B19: ='[3]Data Sheet'!A24 -> Other Expenses | C19: ='[3]Data Sheet'!B24/'[3]Data Sheet'!B$17 -> 0.026183832 | D19: ='[3]Data Sheet'!C24/'[3]Data Sheet'!C$17 -> 0.017094283 | E19: ='[3]Data Sheet'!D24/'[3]Data Sheet'!D$17 -> 0.0022582367 | F19: ='[3]Data Sheet'!E24/'[3]Data Sheet'!E$17 -> 0.0056592338 | G19: ='[3]Data Sheet'!F24/'[3]Data Sheet'!F$17 -> 0.013239885 | H19: ='[3]Data Sheet'!G24/'[3]Data Sheet'!G$17 -> -0.0033407828 | I19: ='[3]Data Sheet'!H24/'[3]Data Sheet'!H$17 -> 0.0044105011 | J19: ='[3]Data Sheet'!I24/'[3]Data Sheet'!I$17 -> 0.014187308 | ... L19: ='[3]Data Sheet'!K24/'[3]Data Sheet'!K$17 -> -0.0077985877
B20: ='[3]Data Sheet'!A25 -> Other Income | C20: ='[3]Data Sheet'!B25/'[3]Data Sheet'!B$17 -> -0.0097771947 | D20: ='[3]Data Sheet'!C25/'[3]Data Sheet'!C$17 -> 0.0069304854 | E20: ='[3]Data Sheet'!D25/'[3]Data Sheet'!D$17 -> 0.020348895 | F20: ='[3]Data Sheet'!E25/'[3]Data Sheet'!E$17 -> -0.088383094 | G20: ='[3]Data Sheet'!F25/'[3]Data Sheet'!F$17 -> 0.00038959203 | H20: ='[3]Data Sheet'!G25/'[3]Data Sheet'!G$17 -> -0.044507861 | I20: ='[3]Data Sheet'!H25/'[3]Data Sheet'!H$17 -> 0.0087053995 | J20: ='[3]Data Sheet'!I25/'[3]Data Sheet'!I$17 -> 0.019261868 | ... L20: ='[3]Data Sheet'!K25/'[3]Data Sheet'!K$17 -> 0.026777653
B21: ='[3]Data Sheet'!A26 -> Depreciation | C21: ='[3]Data Sheet'!B26/'[3]Data Sheet'!B$17 -> 0.061201426 | D21: ='[3]Data Sheet'!C26/'[3]Data Sheet'!C$17 -> 0.066390387 | E21: ='[3]Data Sheet'!D26/'[3]Data Sheet'!D$17 -> 0.073927472 | F21: ='[3]Data Sheet'!E26/'[3]Data Sheet'!E$17 -> 0.078130605 | G21: ='[3]Data Sheet'!F26/'[3]Data Sheet'!F$17 -> 0.082068398 | H21: ='[3]Data Sheet'!G26/'[3]Data Sheet'!G$17 -> 0.094264231 | I21: ='[3]Data Sheet'!H26/'[3]Data Sheet'!H$17 -> 0.089191478 | J21: ='[3]Data Sheet'!I26/'[3]Data Sheet'!I$17 -> 0.071857611 | ... L21: ='[3]Data Sheet'!K26/'[3]Data Sheet'!K$17 -> 0.052891209
B22: ='[3]Data Sheet'!A27 -> Interest | C22: ='[3]Data Sheet'!B27/'[3]Data Sheet'!B$17 -> 0.017905727 | D22: ='[3]Data Sheet'!C27/'[3]Data Sheet'!C$17 -> 0.01571423 | E22: ='[3]Data Sheet'!D27/'[3]Data Sheet'!D$17 -> 0.016058248 | F22: ='[3]Data Sheet'!E27/'[3]Data Sheet'!E$17 -> 0.019072102 | G22: ='[3]Data Sheet'!F27/'[3]Data Sheet'!F$17 -> 0.027744997 | H22: ='[3]Data Sheet'!G27/'[3]Data Sheet'!G$17 -> 0.032415293 | I22: ='[3]Data Sheet'!H27/'[3]Data Sheet'!H$17 -> 0.033441332 | J22: ='[3]Data Sheet'!I27/'[3]Data Sheet'!I$17 -> 0.029556232 | ... L22: ='[3]Data Sheet'!K27/'[3]Data Sheet'!K$17 -> 0.011560286
B23: ='[3]Data Sheet'!A28 -> Profit before tax | C23: ='[3]Data Sheet'!B28/'[3]Data Sheet'!B$17 -> 0.051734106 | D23: ='[3]Data Sheet'!C28/'[3]Data Sheet'!C$17 -> 0.034538557 | E23: ='[3]Data Sheet'!D28/'[3]Data Sheet'!D$17 -> 0.038261059 | F23: ='[3]Data Sheet'!E28/'[3]Data Sheet'!E$17 -> -0.10389917 | G23: ='[3]Data Sheet'!F28/'[3]Data Sheet'!F$17 -> -0.040525768 | H23: ='[3]Data Sheet'!G28/'[3]Data Sheet'!G$17 -> -0.041931546 | I23: ='[3]Data Sheet'!H28/'[3]Data Sheet'!H$17 -> -0.025151083 | J23: ='[3]Data Sheet'!I28/'[3]Data Sheet'!I$17 -> 0.0098099827 | ... L23: ='[3]Data Sheet'!K28/'[3]Data Sheet'!K$17 -> 0.087904115
... B26: ='[3]Data Sheet'!A31 -> Dividend Amount | C26: ='[3]Data Sheet'!B31/'[3]Data Sheet'!B$17 -> 0.00024874966 | D26: ='[3]Data Sheet'!C31/'[3]Data Sheet'!C$17 -> 0 | E26: ='[3]Data Sheet'!D31/'[3]Data Sheet'!D$17 -> 0 | F26: ='[3]Data Sheet'!E31/'[3]Data Sheet'!E$17 -> 0 | G26: ='[3]Data Sheet'!F31/'[3]Data Sheet'!F$17 -> 0 | H26: ='[3]Data Sheet'!G31/'[3]Data Sheet'!G$17 -> 0 | I26: ='[3]Data Sheet'!H31/'[3]Data Sheet'!H$17 -> 0 | J26: ='[3]Data Sheet'!I31/'[3]Data Sheet'!I$17 -> 0.002214142 | ... L26: ='[3]Data Sheet'!K31/'[3]Data Sheet'!K$17 -> 0.0050216627
B27: ='[3]Data Sheet'!A34 -> EBITDA | C27: ='[3]Data Sheet'!B34/'[3]Data Sheet'!B$17 -> 0.13259404 | D27: ='[3]Data Sheet'!C34/'[3]Data Sheet'!C$17 -> 0.12180016 | E27: ='[3]Data Sheet'!D34/'[3]Data Sheet'!D$17 -> 0.13570967 | F27: ='[3]Data Sheet'!E34/'[3]Data Sheet'!E$17 -> -0.0063405317 | G27: ='[3]Data Sheet'!F34/'[3]Data Sheet'!F$17 -> 0.065090942 | H27: ='[3]Data Sheet'!G34/'[3]Data Sheet'!G$17 -> 0.083005548 | I27: ='[3]Data Sheet'!H34/'[3]Data Sheet'!H$17 -> 0.096739163 | J27: ='[3]Data Sheet'!I34/'[3]Data Sheet'!I$17 -> 0.11042728 | ... L27: ='[3]Data Sheet'!K34/'[3]Data Sheet'!K$17 -> 0.15163011
B29: ="Common Sixe Balance Sheet"& " "&" - "&'[3]Data Sheet'!$B$1 -> Common Sixe Balance Sheet - TATA MOTORS LTD
B31: Particulars | C31: ='[3]Data Sheet'!B$16 -> 42460 | D31: ='[3]Data Sheet'!C$16 -> 42825 | E31: ='[3]Data Sheet'!D$16 -> 43190 | F31: ='[3]Data Sheet'!E$16 -> 43555 | G31: ='[3]Data Sheet'!F$16 -> 43921 | H31: ='[3]Data Sheet'!G$16 -> 44286 | I31: ='[3]Data Sheet'!H$16 -> 44651 | J31: ='[3]Data Sheet'!I$16 -> 45016 | ... L31: ='[3]Data Sheet'!K$16 -> 45747
